Workbook

Sheet API Key Details
A1: Name | C1: Status | D1: ID | E1: API key | F1: Description | G1: Creation date
A2: ak-tigomoneyapp-prd-public-dar-api-pa | B2: =VLOOKUP(A2,'API Key & Usage Plan Details'!A:F,4,FALSE) -> ******H5zqrb | C2: Active | D2: y5316nmbo5 | E2: 05SaRlclkj1nZKiPT709E8BpCLvacO2uyQH5zqrb | G2: October 01, 2021, 19:41 (UTC+05:30)
A3: ak-loyalty-prd-public-dar-api-py | B3: =VLOOKUP(A3,'API Key & Usage Plan Details'!A:F,4,FALSE) -> ******yWQqy6 | C3: Active | D3: aupa3y09x6 | E3: 0SFdk8U2CP5zLKc1IVr2a9afSmQ61yN74IyWQqy6 | G3: May 23, 2023, 14:03 (UTC+05:30)
A4: ak-tigosports-prd-public-dar-api-py | B4: =VLOOKUP(A4,'API Key & Usage Plan Details'!A:F,4,FALSE) -> ******GiBg3m | C4: Active | D4: ghgb020mrg | E4: 0cabjJKDKe2elSaL3eyCI8frcik8amlw5HGiBg3m | G4: December 18, 2020, 13:41 (UTC+05:30)
A5: ak-auth0-prd-public-dar-api-sv | B5: =VLOOKUP(A5,'API Key & Usage Plan Details'!A:F,4,FALSE) -> ******nMCyUu | C5: Active | D5: 0xis3vc946 | E5: 0kfv0er0rd18WvvnJ6SrP2i7l74cUlTf2GnMCyUu | G5: May 12, 2023, 12:28 (UTC+05:30)
A6: ak-loyalty-prd-public-dar-api-pa | B6: =VLOOKUP(A6,'API Key & Usage Plan Details'!A:F,4,FALSE) -> ******xhxa4q | C6: Active | D6: 6i7tua1nyh | E6: 1CR6l6obJ63KLIkHkao6G5Gfq7JtxknP1Pxhxa4q | G6: May 23, 2023, 14:02 (UTC+05:30)
A7: ak-oneapp-prd-trusted-dar-api-py | B7: =VLOOKUP(A7,'API Key & Usage Plan Details'!A:F,4,FALSE) -> ******egEDLf | C7: Active | D7: ac49cjw0ed | E7: 1Vb41nqQKH9BdGZJ5BNB47TnmOSo0a3U61egEDLf | G7: February 10, 2021, 19:13 (UTC+05:30)
A8: ak-supermarket-prod-public-dar-api-gt | B8: =VLOOKUP(A8,'API Key & Usage Plan Details'!A:F,4,FALSE) -> ******hWlW1e | C8: Active | D8: 3p1963lv7i | E8: 1VzzKGirSSk8eq6YBcDs5eVuQeIQwa98IMhWlW1e | G8: April 19, 2024, 16:37 (UTC+05:30)
A9: ak-homeactivator-prd-trusted-dar-api-sv | B9: =VLOOKUP(A9,'API Key & Usage Plan Details'!A:F,4,FALSE) -> ******Rd3s7w | C9: Active | D9: 2ajscfewgc | E9: 1W3Sw7cttD21lmopFhpM29tJbLS8rknY3QRd3s7w | G9: June 22, 2020, 21:34 (UTC+05:30)
A10: ak-crmlocal-prd-trusted-dar-api-ni | B10: =VLOOKUP(A10,'API Key & Usage Plan Details'!A:F,4,FALSE) -> ******B99u5M | C10: Active | D10: eaifruni5d | E10: 1a6tCjftvC24am7xn7FmE5BGKbdFCAWl9WB99u5M | G10: July 09, 2020, 22:53 (UTC+05:30)
A11: ak-tigobot-prd-trusted-dar-api-pa | B11: =VLOOKUP(A11,'API Key & Usage Plan Details'!A:F,4,FALSE) -> ******C0oyfL | C11: Active | D11: t1mudxz8s2 | E11: 1d7gRHiqqG9TFbwUNGBSh4juxYKZ2Bi56LC0oyfL | G11: June 23, 2020, 16:56 (UTC+05:30)
A12: ak-expresspayments-prd-trusted-dar-api-hn | B12: =VLOOKUP(A12,'API Key & Usage Plan Details'!A:F,4,FALSE) -> ******Q1cL1G | C12: Active | D12: ug1takejuj | E12: 1xBxP2y7FC8DevI0XjLrJalwKIculHAS2SQ1cL1G | G12: August 23, 2022, 15:24 (UTC+05:30)
A13: ak-loyalty-prd-public-dar-api-bo | B13: =VLOOKUP(A13,'API Key & Usage Plan Details'!A:F,4,FALSE) -> ******6SXK48 | C13: Active | D13: w75vz1dezj | E13: 2BTH6QFDCU4BtYyUB3RsO4ylGvsfjs0dUt6SXK48 | G13: May 23, 2023, 14:02 (UTC+05:30)
... A265: ak-tigo-interactions-prod-public-dar-api-pa | B265: =VLOOKUP(A265,'API Key & Usage Plan Details'!A:F,4,FALSE) -> ******5Ohoh8 | C265: Active | D265: kg7s4za4wd | E265: zpZW3gcmPG1r4TExRBTDv4JB45o9CsNd4a5Ohoh8 | G265: July 04, 2024, 16:49 (UTC+05:30)

Sheet API Key & Usage Plan Details
A1: API Key Name | B1: API Key Channel Group | C1: API Key ID | D1: Masked API key | E1: API key | F1: Usage Plan Name | G1: Usage Plan ID | H1: API Key Channel | I1: API Key Channel Group | J1: API Key Country | K1: Request rate | L1: Burst | M1: Quota | N1: Status | O1: Description | P1: Creation date
A2: ak-oneapp-prd-public-dar-api-co-3 | B2: oneapp | C2: 4ft4svs43c | D2: ******bzP8PB | E2: 5DH9AS6frp1m8vDmV6oo0aBgOyAYyItb5sbzP8PB | F2: up-ak-oneapp-prd-public-dar-api-co-3 | G2: 11pu5a | H2: oneapp-prd-public-dar-api-co-3 | I2: oneapp | J2: co | K2: 100 per second | L2: 50 | M2: - | N2: Active | P2: May 31, 2023, 13:49 (UTC+05:30)
A3: ak-oneappweb-prd-public-dar-api-co-3 | B3: oneappweb | C3: 4cf5nuu5f1 | D3: ******RWqRd0 | E3: jnc83k3dlMFBMOxKA19q6wSyeLiO8dLpHURWqRd0 | F3: up-ak-oneappweb-prd-public-dar-api-co-3 | G3: j9gh0x | H3: oneappweb-prd-public-dar-api-co-3 | I3: oneappweb | J3: co | K3: 100 per second | L3: 50 | M3: - | N3: Active | P3: May 31, 2023, 13:29 (UTC+05:30)
A4: ak-auth0-prd-public-dar-api-bo | B4: auth0 | C4: ia4pykd9fa | D4: ******57LBpb | E4: LkcI8ie3SxaYkVyRYhCSB5QWh7ee5Ws67r57LBpb | F4: up-auth0-prd-public-dar-api-bo | G4: 7ocg79 | H4: auth0-prd-public-dar-api-bo | I4: auth0 | J4: bo | K4: 50 per second | L4: 25 | M4: - | N4: Active | P4: May 12, 2023, 12:17 (UTC+05:30)
A5: ak-auth0-prd-public-dar-api-co | B5: auth0 | C5: 16n14fkgnb | D5: ******qCzDMP | E5: DXuhtWdlSq38MmfyTylnE6wCz4ethQYU5TqCzDMP | F5: up-auth0-prd-public-dar-api-co | G5: xfkphq | H5: auth0-prd-public-dar-api-co | I5: auth0 | J5: co | K5: 50 per second | L5: 25 | M5: - | N5: Active | P5: April 04, 2023, 17:00 (UTC+05:30)
A6: ak-auth0-prd-public-dar-api-gt | B6: auth0 | C6: a6uo3eumib | D6: ******bGxVWK | E6: KEAglP4gSTatYtP1LdgnN4yNZMSSFBSaaAbGxVWK | F6: up-auth0-prd-public-dar-api-gt | G6: iyv6ic | H6: auth0-prd-public-dar-api-gt | I6: auth0 | J6: gt | K6: 50 per second | L6: 25 | M6: - | N6: Active | P6: April 04, 2023, 17:00 (UTC+05:30)
A7: ak-auth0-prd-public-dar-api-hn | B7: auth0 | C7: u33abienrg | D7: ******wScnTD | E7: SijFfyTRsc47cBi2cEeFk2KSnIsULCyQa7wScnTD | F7: up-auth0-prd-public-dar-api-hn | G7: djyod8 | H7: auth0-prd-public-dar-api-hn | I7: auth0 | J7: hn | K7: 50 per second | L7: 25 | M7: - | N7: Active | P7: April 04, 2023, 17:00 (UTC+05:30)
A8: ak-auth0-prd-public-dar-api-ni | B8: auth0 | C8: fexq8jpobb | D8: ******04N68f | E8: ELExhEmQT98XYrYuvfVmf9fekYvYtcDh9v04N68f | F8: up-auth0-prd-public-dar-api-ni | G8: 7midm7 | H8: auth0-prd-public-dar-api-ni | I8: auth0 | J8: ni | K8: 50 per second | L8: 25 | M8: - | N8: Active | P8: February 20, 2023, 14:46 (UTC+05:30)
A9: ak-auth0-prd-public-dar-api-pa | B9: auth0 | C9: wlyy5g8kdh | D9: ******6J67mw | E9: Oe6kPNcjjT8s5GL18USWp3Y0HCKDyLfw8a6J67mw | F9: up-auth0-prd-public-dar-api-pa | G9: 424vzh | H9: auth0-prd-public-dar-api-pa | I9: auth0 | J9: pa | K9: 50 per second | L9: 25 | M9: - | N9: Active | P9: February 20, 2023, 14:47 (UTC+05:30)
A10: ak-auth0-prd-public-dar-api-py | B10: auth0 | C10: jbk0c6sr5d | D10: ******ifAZ34 | E10: kKp70jI88I1jmqMxXBByADSdLGtlRUM5EIifAZ34 | F10: up-auth0-prd-public-dar-api-py | G10: bawrhl | H10: auth0-prd-public-dar-api-py | I10: auth0 | J10: py | K10: 50 per second | L10: 25 | M10: - | N10: Active | P10: May 12, 2023, 12:26 (UTC+05:30)
A11: ak-auth0-prd-public-dar-api-sv | B11: auth0 | C11: 0xis3vc946 | D11: ******nMCyUu | E11: 0kfv0er0rd18WvvnJ6SrP2i7l74cUlTf2GnMCyUu | F11: up-auth0-prd-public-dar-api-sv | G11: ssdr81 | H11: auth0-prd-public-dar-api-sv | I11: auth0 | J11: sv | K11: 250 per second | L11: 25 | M11: - | N11: Active | P11: May 12, 2023, 12:28 (UTC+05:30)
A12: ak-auth0-prd-public-dar-api-us | B12: auth0 | C12: qrec5mjadj | D12: ******qESMk5 | E12: ohSc9JshRi8htny4n4ZKG4tvSUihhlYAH8qESMk5 | F12: up-auth0-prd-public-dar-api-us | G12: 3egi77 | H12: auth0-prd-public-dar-api-us | I12: auth0 | J12: us | K12: 50 per second | L12: 25 | M12: - | N12: Active | P12: September 04, 2023, 15:57 (UTC+05:30)
A13: ak-auth0-prd-trusted-dar-api-bo | B13: auth0 | C13: py5drewf40 | D13: ******i3b9Eu | E13: SuJfQuSs1i4STY4sdfM3Y5CUrRg1du01api3b9Eu | F13: up-auth0-prd-trusted-dar-api-bo | G13: f9t6c5 | H13: auth0-prd-trusted-dar-api-bo | I13: auth0 | J13: bo | K13: 500 per second | L13: 50 | M13: - | N13: Active | P13: May 12, 2023, 12:24 (UTC+05:30)
... A22: ak-auth0-prd-trusted-dar-api-us | B22: auth0 | C22: 1nlhdy8xfb | D22: ******73JiO5 | E22: a3DKz8zXzr2GGEvPq0DK7Q9bXVBIfcF7OX73JiO5 | F22: up-auth0-prd-trusted-dar-api-us | G22: h5q8w6 | H22: auth0-prd-trusted-dar-api-us | I22: auth0 | J22: us | K22: 50 per second | L22: 25 | M22: - | N22: Active | P22: September 04, 2023, 15:56 (UTC+05:30)
A23: #N/A | B23: #N/A | C23: #N/A | D23: #N/A | E23: #N/A | F23: up-auth0federated-dev-trusted-dar-api-all | G23: hitm8z | H23: #N/A | I23: #N/A | K23: - | L23: - | M23: - | N23: #N/A | P23: #N/A
A24: ak-auth0federated-prod-trusted-dar-api-all | B24: auth0federated | C24: 8ickv81su6 | D24: ******MtbhKQ | E24: 70XiQpoE4h47jdVJM3x9M7GUtm7Y3qvZ7fMtbhKQ | F24: up-auth0federated-prod-trusted-dar-api-all | G24: f6q81u | H24: auth0federated-prod-trusted-dar-api-all | I24: auth0federated | J24: all | K24: 50 per second | L24: 25 | M24: - | N24: Active | P24: May 20, 2024, 20:24 (UTC+05:30)
A25: ak-auth0he-prd-trusted-dar-api-bo | B25: auth0he | C25: 65mkwcqmrd | D25: ******OrzHaN | E25: tYj3le2sTd7cg5GOvWWAA5630UaQ4fWy8LOrzHaN | F25: up-auth0he-prd-trusted-dar-api-bo | G25: zry176 | H25: auth0he-prd-trusted-dar-api-bo | I25: auth0he | J25: bo | K25: 50 per second | L25: 25 | M25: - | N25: Active | P25: May 11, 2023, 12:06 (UTC+05:30)
A26: ak-auth0he-prd-trusted-dar-api-co | B26: auth0he | C26: vb0yoqjyyk | D26: ******ZWN0Vb | E26: wdKteRG9Gw4142nnvQanp6UESYIMlnCa7tZWN0Vb | F26: up-auth0he-prd-trusted-dar-api-co | G26: g4cjd8 | H26: auth0he-prd-trusted-dar-api-co | I26: auth0he | J26: co | K26: 100 per second | L26: 50 | M26: - | N26: Active | P26: May 11, 2023, 12:06 (UTC+05:30)
A27: ak-auth0he-prd-trusted-dar-api-gt | B27: auth0he | C27: uq5o4qvnp9 | D27: ******e0rmDO | E27: o8t07PPbrv8Gh56JzieTP7A5pqV0iedp8Ve0rmDO | F27: up-auth0he-prd-trusted-dar-api-gt | G27: 0eezlu | H27: auth0he-prd-trusted-dar-api-gt | I27: auth0he | J27: gt | K27: 100 per second | L27: 50 | M27: - | N27: Active | P27: May 11, 2023, 12:07 (UTC+05:30)
A28: ak-auth0he-prd-trusted-dar-api-hn | B28: auth0he | C28: qh7amjgefj | D28: ******xWJLgS | E28: TiunLL2Ztv8SnE8RthiZy2muq4zYLibo1hxWJLgS | F28: up-auth0he-prd-trusted-dar-api-hn | G28: su0gnr | H28: auth0he-prd-trusted-dar-api-hn | I28: auth0he | J28: hn | K28: 50 per second | L28: 25 | M28: - | N28: Active | P28: May 11, 2023, 12:06 (UTC+05:30)
A29: ak-auth0he-prd-trusted-dar-api-ni | B29: auth0he | C29: t0psaagxm6 | D29: ******uiDaVh | E29: UEiJLZdMfa5eYd27lsH5B2bhWkaCoWVSf9uiDaVh | F29: up-auth0he-prd-trusted-dar-api-ni | G29: 1chd4r | H29: auth0he-prd-trusted-dar-api-ni | I29: auth0he | J29: ni | K29: 50 per second | L29: 25 | M29: - | N29: Active | P29: October 13, 2023, 14:22 (UTC+05:30)
A30: ak-auth0he-prd-trusted-dar-api-pa | B30: auth0he | C30: fyn1nwbj1f | D30: ******GqbO9U | E30: l89DV0YGRR5W0sRcqHdEF212P74JVKQHa2GqbO9U | F30: up-auth0he-prd-trusted-dar-api-pa | G30: xygrca | H30: auth0he-prd-trusted-dar-api-pa | I30: auth0he | J30: pa | K30: 50 per second | L30: 25 | M30: - | N30: Active | P30: May 24, 2023, 11:17 (UTC+05:30)
A31: ak-auth0he-prd-trusted-dar-api-py | B31: auth0he | C31: rbhl0wqrt5 | D31: ******sQAtG1 | E31: Tr5UlHIssc3lGVlEsZm7S9z0GN5ryU8k61sQAtG1 | F31: up-auth0he-prd-trusted-dar-api-py | G31: s7axd2 | H31: auth0he-prd-trusted-dar-api-py | I31: auth0he | J31: py | K31: 50 per second | L31: 25 | M31: - | N31: Active | P31: May 11, 2023, 12:07 (UTC+05:30)
A32: ak-auth0he-prd-trusted-dar-api-sv | B32: auth0he | C32: dkp0pohnd3 | D32: ******QXfADO | E32: m2SX4yDje42cznbPhPVe16HwluDtT8Oa6yQXfADO | F32: up-auth0he-prd-trusted-dar-api-sv | G32: fv2kb4 | H32: auth0he-prd-trusted-dar-api-sv | I32: auth0he | J32: sv | K32: 50 per second | L32: 25 | M32: - | N32: Active | P32: May 11, 2023, 12:07 (UTC+05:30)
A33: ak-caas-prd-trusted-dar-api-all | B33: caas | C33: 2prnf6zrvg | D33: ******0d7nuQ | E33: rYHHZaY5vH9hnt3Ab7J6M2gD4EHHkeVG3g0d7nuQ | F33: up-caas-prd-trusted-dar-api-all | G33: 4k5n9l | H33: caas-prd-trusted-dar-api-all | I33: caas | J33: all | K33: 50 per second | L33: 25 | M33: - | N33: Active | P33: August 21, 2023, 14:14 (UTC+05:30)
A34: ak-campaigns-prd-trusted-dar-api-bo | B34: campaigns | C34: u137sxohrl | D34: ******xDD4vO | E34: LB2SFIUKfL5gJIMwmtXVx3kBAuTxDSoK7wxDD4vO | F34: up-campaigns-prd-trusted-dar-api-bo | G34: gloduc | H34: campaigns-prd-trusted-dar-api-bo | I34: campaigns | J34: bo | K34: 10 per second | L34: 5 | M34: - | N34: Active | P34: August 05, 2020, 19:27 (UTC+05:30)
A35: ak-campaigns-prd-trusted-dar-api-co | B35: campaigns | C35: 9q5ea2sbx4 | D35: ******eYtAGU | E35: BOamcLSnLt7wOX3WvJ2h3731EBBCxYik9reYtAGU | F35: up-campaigns-prd-trusted-dar-api-co | G35: 9q287t | H35: campaigns-prd-trusted-dar-api-co | I35: campaigns | J35: co | K35: 10 per second | L35: 5 | M35: - | N35: Active | P35: August 05, 2020, 19:27 (UTC+05:30)
... A51: ak-crmlocal-prd-trusted-dar-api-sv | B51: crmlocal | C51: rlo0v1yvr9 | D51: ******iQyz1U | E51: bz7jiXVeaJ9Kcg3qIwv152SAgLkMDqx94iiQyz1U | F51: up-crmlocal-prd-trusted-dar-api-sv | G51: oqvrgz | H51: crmlocal-prd-trusted-dar-api-sv | I51: crmlocal | J51: sv | K51: 15 per second | L51: 8 | M51: - | N51: Active | P51: July 09, 2020, 22:52 (UTC+05:30)
A52: ak-dar-api-prd-cmv-sectest-all | B52: dar | C52: g6yi5rh6e3 | D52: ******kS5kSc | E52: HwfHpLlYj43Ph8b2g2MpS9tqvJ835bZn3LkS5kSc | F52: up-dar-api-prd-cmv-sectest-all | G52: g017u8 | H52: dar-api-prd-cmv-sectest-all | I52: dar | J52: all | K52: - | L52: - | M52: - | N52: Active | P52: January 21, 2021, 21:11 (UTC+05:30)
A53: ak-dar-api-prd-party-sectest-all | B53: dar | C53: h7fr1jmpbh | D53: ******ginQdq | E53: ipON4qWQ7Y2jClSxeoeDO2HDFtwxpTMp1yginQdq | F53: up-dar-api-prd-party-sectest-all | G53: fuz172 | H53: dar-api-prd-party-sectest-all | I53: dar | J53: all | K53: - | L53: - | M53: - | N53: Active | P53: January 21, 2021, 21:10 (UTC+05:30)
A54: ak-dataservices-prd-trusted-dar-api-co | B54: dataservices | C54: hy7oj273r7 | D54: ******3wNvSu | E54: 6BVvrySsMI2pNDwqLEy1m5OqXCu3voy27A3wNvSu | F54: up-dataservices-prd-trusted-dar-api-co | G54: ffr7q9 | H54: dataservices-prd-trusted-dar-api-co | I54: dataservices | J54: co | K54: 50 per second | L54: 25 | M54: - | N54: Active | P54: March 08, 2023, 12:19 (UTC+05:30)
A55: ak-discovery-backend-prd-trusted-dar-api-co | B55: discovery | C55: peu59o41oa | D55: ******3S7UaY | E55: apzHpxNU0N5uG3egka2IJ4gHp7HV95bB5n3S7UaY | F55: up-discovery-backend-prd-trusted-dar-api-co | G55: ujwwlu | H55: discovery-backend-prd-trusted-dar-api-co | I55: discovery | J55: co | K55: 10 per second | L55: 10 | M55: - | N55: Active | P55: May 23, 2023, 14:07 (UTC+05:30)
A56: ak-ecommerce-prd-trusted-dar-api-bo | B56: ecommerce | C56: exsy33enkg | D56: ******TLuke8 | E56: Oamnh38vFW9smSkdkrXGyaCaGf26YLI5aZTLuke8 | F56: up-ecommerce-prd-trusted-dar-api-bo | G56: 31evbq | H56: ecommerce-prd-trusted-dar-api-bo | I56: ecommerce | J56: bo | K56: 15 per second | L56: 8 | M56: - | N56: Active | P56: April 08, 2022, 08:29 (UTC+05:30)
A57: ak-ecommerce-prd-trusted-dar-api-co | B57: ecommerce | C57: d1i056tonb | D57: ******x9lzGT | E57: H3cxa9sbfA6MqEjP1YaBV9ZfWE6uvwD58ix9lzGT | F57: up-ecommerce-prd-trusted-dar-api-co | G57: mz7gyu | H57: ecommerce-prd-trusted-dar-api-co | I57: ecommerce | J57: co | K57: 15 per second | L57: 8 | M57: - | N57: Active | P57: April 08, 2022, 08:29 (UTC+05:30)
A58: ak-ecommerce-prd-trusted-dar-api-cr | B58: ecommerce | C58: sqewar70o2 | D58: ******8SaMRQ | E58: wRIFXxrFK78IN2PwliPhW8uEaRlcL6qi5F8SaMRQ | F58: up-ecommerce-prd-trusted-dar-api-cr | G58: pgzbhd | H58: ecommerce-prd-trusted-dar-api-cr | I58: ecommerce | J58: cr | K58: 15 per second | L58: 8 | M58: - | N58: Active | P58: April 08, 2022, 08:29 (UTC+05:30)
A59: ak-ecommerce-prd-trusted-dar-api-gt | B59: ecommerce | C59: zdj5k314f1 | D59: ******OR7dX4 | E59: CezOySFab3NDeqSYYMJe2tDwC5eheYbaj9OR7dX4 | F59: up-ecommerce-prd-trusted-dar-api-gt | G59: 4ad2wy | H59: ecommerce-prd-trusted-dar-api-gt | I59: ecommerce | J59: gt | K59: 15 per second | L59: 8 | M59: - | N59: Active | P59: April 08, 2022, 08:30 (UTC+05:30)
A60: ak-ecommerce-prd-trusted-dar-api-hn | B60: ecommerce | C60: i5qkaxxy8c | D60: ******cRc3HV | E60: ng5ra4LLOE1q0ARJ9YjEq3lqgAK2UqRe5ucRc3HV | F60: up-ecommerce-prd-trusted-dar-api-hn | G60: t8ckbq | H60: ecommerce-prd-trusted-dar-api-hn | I60: ecommerce | J60: hn | K60: 15 per second | L60: 8 | M60: - | N60: Active | P60: April 08, 2022, 08:29 (UTC+05:30)
A61: ak-ecommerce-prd-trusted-dar-api-ni | B61: ecommerce | C61: q31f7ibofj | D61: ******lXLJgd | E61: XRwrX9hj5c6PmB8NYaApP8Ah6FvJUd6k2MlXLJgd | F61: up-ecommerce-prd-trusted-dar-api-ni | G61: 6g68a3 | H61: ecommerce-prd-trusted-dar-api-ni | I61: ecommerce | J61: ni | K61: 15 per second | L61: 8 | M61: - | N61: Active | P61: April 08, 2022, 08:30 (UTC+05:30)
A62: ak-ecommerce-prd-trusted-dar-api-pa | B62: ecommerce | C62: romdgtfs34 | D62: ******OT8upe | E62: JRhrEzVFcs5yyoNaozGwN1NvjWNSSEbhboOT8upe | F62: up-ecommerce-prd-trusted-dar-api-pa | G62: 3wfdq2 | H62: ecommerce-prd-trusted-dar-api-pa | I62: ecommerce | J62: pa | K62: 15 per second | L62: 8 | M62: - | N62: Active | P62: April 08, 2022, 08:30 (UTC+05:30)
A63: ak-ecommerce-prd-trusted-dar-api-py | B63: ecommerce | C63: hz86777fcf | D63: ******KmW6Rg | E63: BMrAYpd4Mr1ZV7yEXh80r1zA2otXF8cF8CKmW6Rg | F63: up-ecommerce-prd-trusted-dar-api-py | G63: 2nxgx1 | H63: ecommerce-prd-trusted-dar-api-py | I63: ecommerce | J63: py | K63: 15 per second | L63: 8 | M63: - | N63: Active | P63: April 08, 2022, 08:30 (UTC+05:30)
...
